[2025-09-10T06:51:13.417+0000] {local_task_job_runner.py:123} INFO - ::group::Pre task execution logs
[2025-09-10T06:51:13.424+0000] {taskinstance.py:2612} INFO - Dependencies all met for dep_context=non-requeueable deps ti=<TaskInstance: espn_news_pipeline.pull_api scheduled__2025-08-31T07:00:00+00:00 [queued]>
[2025-09-10T06:51:13.427+0000] {taskinstance.py:2612} INFO - Dependencies all met for dep_context=requeueable deps ti=<TaskInstance: espn_news_pipeline.pull_api scheduled__2025-08-31T07:00:00+00:00 [queued]>
[2025-09-10T06:51:13.427+0000] {taskinstance.py:2865} INFO - Starting attempt 1 of 1
[2025-09-10T06:51:13.431+0000] {taskinstance.py:2888} INFO - Executing <Task(PythonOperator): pull_api> on 2025-08-31 07:00:00+00:00
[2025-09-10T06:51:13.433+0000] {standard_task_runner.py:72} INFO - Started process 34 to run task
[2025-09-10T06:51:13.436+0000] {standard_task_runner.py:104} INFO - Running: ['***', 'tasks', 'run', 'espn_news_pipeline', 'pull_api', 'scheduled__2025-08-31T07:00:00+00:00', '--job-id', '63', '--raw', '--subdir', 'DAGS_FOLDER/news_pipeline.py', '--cfg-path', '/tmp/tmpjqncmkoi']
[2025-09-10T06:51:13.440+0000] {standard_task_runner.py:105} INFO - Job 63: Subtask pull_api
[2025-09-10T06:51:13.470+0000] {task_command.py:467} INFO - Running <TaskInstance: espn_news_pipeline.pull_api scheduled__2025-08-31T07:00:00+00:00 [running]> on host 21177f6a7d07
[2025-09-10T06:51:13.541+0000] {taskinstance.py:3131} INFO - Exporting env vars: AIRFLOW_CTX_DAG_OWNER='***' AIRFLOW_CTX_DAG_ID='espn_news_pipeline' AIRFLOW_CTX_TASK_ID='pull_api' AIRFLOW_CTX_EXECUTION_DATE='2025-08-31T07:00:00+00:00' AIRFLOW_CTX_TRY_NUMBER='1' AIRFLOW_CTX_DAG_RUN_ID='scheduled__2025-08-31T07:00:00+00:00'
[2025-09-10T06:51:13.543+0000] {taskinstance.py:731} INFO - ::endgroup::
[2025-09-10T06:51:14.688+0000] {connection.py:408} INFO - Snowflake Connector for Python Version: 3.11.0, Python Version: 3.11.10, Platform: Linux-6.10.14-linuxkit-aarch64-with-glibc2.36
[2025-09-10T06:51:14.691+0000] {taskinstance.py:3310} ERROR - Task failed with exception
Traceback (most recent call last):
  File "/home/airflow/.local/lib/python3.11/site-packages/airflow/models/taskinstance.py", line 767, in _execute_task
    result = _execute_callable(context=context, **execute_callable_kwargs)
             ^^^^^^^^^^^^^^^^^^^^^^^^^^^^^^^^^^^^^^^^^^^^^^^^^^^^^^^^^^^^^
  File "/home/airflow/.local/lib/python3.11/site-packages/airflow/models/taskinstance.py", line 733, in _execute_callable
    return ExecutionCallableRunner(
           ^^^^^^^^^^^^^^^^^^^^^^^^
  File "/home/airflow/.local/lib/python3.11/site-packages/airflow/utils/operator_helpers.py", line 252, in run
    return self.func(*args, **kwargs)
           ^^^^^^^^^^^^^^^^^^^^^^^^^^
  File "/home/airflow/.local/lib/python3.11/site-packages/airflow/models/baseoperator.py", line 406, in wrapper
    return func(self, *args, **kwargs)
           ^^^^^^^^^^^^^^^^^^^^^^^^^^^
  File "/home/airflow/.local/lib/python3.11/site-packages/airflow/operators/python.py", line 238, in execute
    return_value = self.execute_callable()
                   ^^^^^^^^^^^^^^^^^^^^^^^
  File "/home/airflow/.local/lib/python3.11/site-packages/airflow/operators/python.py", line 256, in execute_callable
    return runner.run(*self.op_args, **self.op_kwargs)
           ^^^^^^^^^^^^^^^^^^^^^^^^^^^^^^^^^^^^^^^^^^^
  File "/home/airflow/.local/lib/python3.11/site-packages/airflow/utils/operator_helpers.py", line 252, in run
    return self.func(*args, **kwargs)
           ^^^^^^^^^^^^^^^^^^^^^^^^^^
  File "/opt/airflow/dags/news_pipeline.py", line 16, in run_etl
    load_insert_raw()
  File "/opt/airflow/espn_etl/scripts/load_videos.py", line 21, in load_insert_raw
    conn = connect_to_schema()
           ^^^^^^^^^^^^^^^^^^^
  File "/opt/airflow/espn_etl/backend/snowflake_connect.py", line 8, in connect_to_schema
    conn = snowflake.connector.connect(
           ^^^^^^^^^^^^^^^^^^^^^^^^^^^^
  File "/home/airflow/.local/lib/python3.11/site-packages/snowflake/connector/__init__.py", line 55, in Connect
    return SnowflakeConnection(**kwargs)
           ^^^^^^^^^^^^^^^^^^^^^^^^^^^^^
  File "/home/airflow/.local/lib/python3.11/site-packages/snowflake/connector/connection.py", line 451, in __init__
    self.connect(**kwargs)
  File "/home/airflow/.local/lib/python3.11/site-packages/snowflake/connector/connection.py", line 716, in connect
    self.__config(**kwargs)
  File "/home/airflow/.local/lib/python3.11/site-packages/snowflake/connector/connection.py", line 1207, in __config
    Error.errorhandler_wrapper(
  File "/home/airflow/.local/lib/python3.11/site-packages/snowflake/connector/errors.py", line 290, in errorhandler_wrapper
    handed_over = Error.hand_to_other_handler(
                  ^^^^^^^^^^^^^^^^^^^^^^^^^^^^
  File "/home/airflow/.local/lib/python3.11/site-packages/snowflake/connector/errors.py", line 348, in hand_to_other_handler
    connection.errorhandler(connection, cursor, error_class, error_value)
  File "/home/airflow/.local/lib/python3.11/site-packages/snowflake/connector/errors.py", line 221, in default_errorhandler
    raise error_class(
snowflake.connector.errors.ProgrammingError: 251005: 251005: User is empty
[2025-09-10T06:51:14.697+0000] {taskinstance.py:1225} INFO - Marking task as FAILED. dag_id=espn_news_pipeline, task_id=pull_api, run_id=scheduled__2025-08-31T07:00:00+00:00, execution_date=20250831T070000, start_date=20250910T065113, end_date=20250910T065114
[2025-09-10T06:51:14.702+0000] {taskinstance.py:340} INFO - ::group::Post task execution logs
[2025-09-10T06:51:14.702+0000] {standard_task_runner.py:124} ERROR - Failed to execute job 63 for task pull_api (251005: 251005: User is empty; 34)
Traceback (most recent call last):
  File "/home/airflow/.local/lib/python3.11/site-packages/airflow/task/task_runner/standard_task_runner.py", line 117, in _start_by_fork
    ret = args.func(args, dag=self.dag)
          ^^^^^^^^^^^^^^^^^^^^^^^^^^^^^
  File "/home/airflow/.local/lib/python3.11/site-packages/airflow/cli/cli_config.py", line 49, in command
    return func(*args, **kwargs)
           ^^^^^^^^^^^^^^^^^^^^^
  File "/home/airflow/.local/lib/python3.11/site-packages/airflow/utils/cli.py", line 115, in wrapper
    return f(*args, **kwargs)
           ^^^^^^^^^^^^^^^^^^
  File "/home/airflow/.local/lib/python3.11/site-packages/airflow/cli/commands/task_command.py", line 483, in task_run
    task_return_code = _run_task_by_selected_method(args, _dag, ti)
                       ^^^^^^^^^^^^^^^^^^^^^^^^^^^^^^^^^^^^^^^^^^^^
  File "/home/airflow/.local/lib/python3.11/site-packages/airflow/cli/commands/task_command.py", line 256, in _run_task_by_selected_method
    return _run_raw_task(args, ti)
           ^^^^^^^^^^^^^^^^^^^^^^^
  File "/home/airflow/.local/lib/python3.11/site-packages/airflow/cli/commands/task_command.py", line 341, in _run_raw_task
    return ti._run_raw_task(
           ^^^^^^^^^^^^^^^^^
  File "/home/airflow/.local/lib/python3.11/site-packages/airflow/utils/session.py", line 97, in wrapper
    return func(*args, session=session, **kwargs)
           ^^^^^^^^^^^^^^^^^^^^^^^^^^^^^^^^^^^^^^
  File "/home/airflow/.local/lib/python3.11/site-packages/airflow/models/taskinstance.py", line 3004, in _run_raw_task
    return _run_raw_task(
           ^^^^^^^^^^^^^^
  File "/home/airflow/.local/lib/python3.11/site-packages/airflow/models/taskinstance.py", line 273, in _run_raw_task
    TaskInstance._execute_task_with_callbacks(
  File "/home/airflow/.local/lib/python3.11/site-packages/airflow/models/taskinstance.py", line 3158, in _execute_task_with_callbacks
    result = self._execute_task(context, task_orig)
             ^^^^^^^^^^^^^^^^^^^^^^^^^^^^^^^^^^^^^^
  File "/home/airflow/.local/lib/python3.11/site-packages/airflow/models/taskinstance.py", line 3182, in _execute_task
    return _execute_task(self, context, task_orig)
           ^^^^^^^^^^^^^^^^^^^^^^^^^^^^^^^^^^^^^^^
  File "/home/airflow/.local/lib/python3.11/site-packages/airflow/models/taskinstance.py", line 767, in _execute_task
    result = _execute_callable(context=context, **execute_callable_kwargs)
             ^^^^^^^^^^^^^^^^^^^^^^^^^^^^^^^^^^^^^^^^^^^^^^^^^^^^^^^^^^^^^
  File "/home/airflow/.local/lib/python3.11/site-packages/airflow/models/taskinstance.py", line 733, in _execute_callable
    return ExecutionCallableRunner(
           ^^^^^^^^^^^^^^^^^^^^^^^^
  File "/home/airflow/.local/lib/python3.11/site-packages/airflow/utils/operator_helpers.py", line 252, in run
    return self.func(*args, **kwargs)
           ^^^^^^^^^^^^^^^^^^^^^^^^^^
  File "/home/airflow/.local/lib/python3.11/site-packages/airflow/models/baseoperator.py", line 406, in wrapper
    return func(self, *args, **kwargs)
           ^^^^^^^^^^^^^^^^^^^^^^^^^^^
  File "/home/airflow/.local/lib/python3.11/site-packages/airflow/operators/python.py", line 238, in execute
    return_value = self.execute_callable()
                   ^^^^^^^^^^^^^^^^^^^^^^^
  File "/home/airflow/.local/lib/python3.11/site-packages/airflow/operators/python.py", line 256, in execute_callable
    return runner.run(*self.op_args, **self.op_kwargs)
           ^^^^^^^^^^^^^^^^^^^^^^^^^^^^^^^^^^^^^^^^^^^
  File "/home/airflow/.local/lib/python3.11/site-packages/airflow/utils/operator_helpers.py", line 252, in run
    return self.func(*args, **kwargs)
           ^^^^^^^^^^^^^^^^^^^^^^^^^^
  File "/opt/airflow/dags/news_pipeline.py", line 16, in run_etl
    load_insert_raw()
  File "/opt/airflow/espn_etl/scripts/load_videos.py", line 21, in load_insert_raw
    conn = connect_to_schema()
           ^^^^^^^^^^^^^^^^^^^
  File "/opt/airflow/espn_etl/backend/snowflake_connect.py", line 8, in connect_to_schema
    conn = snowflake.connector.connect(
           ^^^^^^^^^^^^^^^^^^^^^^^^^^^^
  File "/home/airflow/.local/lib/python3.11/site-packages/snowflake/connector/__init__.py", line 55, in Connect
    return SnowflakeConnection(**kwargs)
           ^^^^^^^^^^^^^^^^^^^^^^^^^^^^^
  File "/home/airflow/.local/lib/python3.11/site-packages/snowflake/connector/connection.py", line 451, in __init__
    self.connect(**kwargs)
  File "/home/airflow/.local/lib/python3.11/site-packages/snowflake/connector/connection.py", line 716, in connect
    self.__config(**kwargs)
  File "/home/airflow/.local/lib/python3.11/site-packages/snowflake/connector/connection.py", line 1207, in __config
    Error.errorhandler_wrapper(
  File "/home/airflow/.local/lib/python3.11/site-packages/snowflake/connector/errors.py", line 290, in errorhandler_wrapper
    handed_over = Error.hand_to_other_handler(
                  ^^^^^^^^^^^^^^^^^^^^^^^^^^^^
  File "/home/airflow/.local/lib/python3.11/site-packages/snowflake/connector/errors.py", line 348, in hand_to_other_handler
    connection.errorhandler(connection, cursor, error_class, error_value)
  File "/home/airflow/.local/lib/python3.11/site-packages/snowflake/connector/errors.py", line 221, in default_errorhandler
    raise error_class(
snowflake.connector.errors.ProgrammingError: 251005: 251005: User is empty
[2025-09-10T06:51:14.739+0000] {local_task_job_runner.py:266} INFO - Task exited with return code 1
[2025-09-10T06:51:14.749+0000] {taskinstance.py:3900} INFO - 0 downstream tasks scheduled from follow-on schedule check
[2025-09-10T06:51:14.751+0000] {local_task_job_runner.py:245} INFO - ::endgroup::
