[2025-09-20T23:08:00.974+0000] {local_task_job_runner.py:120} INFO - ::group::Pre task execution logs
[2025-09-20T23:08:00.983+0000] {taskinstance.py:2076} INFO - Dependencies all met for dep_context=non-requeueable deps ti=<TaskInstance: espn_news_pipeline.dbt_run manual__2025-09-20T23:07:46.340585+00:00 [queued]>
[2025-09-20T23:08:00.986+0000] {taskinstance.py:2076} INFO - Dependencies all met for dep_context=requeueable deps ti=<TaskInstance: espn_news_pipeline.dbt_run manual__2025-09-20T23:07:46.340585+00:00 [queued]>
[2025-09-20T23:08:00.986+0000] {taskinstance.py:2306} INFO - Starting attempt 1 of 1
[2025-09-20T23:08:00.990+0000] {taskinstance.py:2330} INFO - Executing <Task(BashOperator): dbt_run> on 2025-09-20 23:07:46.340585+00:00
[2025-09-20T23:08:00.992+0000] {standard_task_runner.py:64} INFO - Started process 102 to run task
[2025-09-20T23:08:00.993+0000] {standard_task_runner.py:90} INFO - Running: ['airflow', 'tasks', 'run', 'espn_news_pipeline', 'dbt_run', 'manual__2025-09-20T23:07:46.340585+00:00', '--job-id', '9', '--raw', '--subdir', 'DAGS_FOLDER/news_pipeline.py', '--cfg-path', '/tmp/tmpfh_e22f2']
[2025-09-20T23:08:00.994+0000] {standard_task_runner.py:91} INFO - Job 9: Subtask dbt_run
[2025-09-20T23:08:01.007+0000] {task_command.py:426} INFO - Running <TaskInstance: espn_news_pipeline.dbt_run manual__2025-09-20T23:07:46.340585+00:00 [running]> on host 6146678ba62d
[2025-09-20T23:08:01.030+0000] {taskinstance.py:2648} INFO - Exporting env vars: AIRFLOW_CTX_DAG_OWNER='airflow' AIRFLOW_CTX_DAG_ID='espn_news_pipeline' AIRFLOW_CTX_TASK_ID='dbt_run' AIRFLOW_CTX_EXECUTION_DATE='2025-09-20T23:07:46.340585+00:00' AIRFLOW_CTX_TRY_NUMBER='1' AIRFLOW_CTX_DAG_RUN_ID='manual__2025-09-20T23:07:46.340585+00:00'
[2025-09-20T23:08:01.030+0000] {taskinstance.py:430} INFO - ::endgroup::
[2025-09-20T23:08:01.035+0000] {subprocess.py:63} INFO - Tmp dir root location: /tmp
[2025-09-20T23:08:01.035+0000] {subprocess.py:75} INFO - Running command: ['/usr/bin/bash', '-c', 'cd $DBT_PROJECT_DIR && /home/airflow/.local/bin/dbt run']
[2025-09-20T23:08:01.038+0000] {subprocess.py:86} INFO - Output:
[2025-09-20T23:08:01.879+0000] {subprocess.py:93} INFO - [0m23:08:01  Running with dbt=1.8.9
[2025-09-20T23:08:02.270+0000] {subprocess.py:93} INFO - [0m23:08:02  Registered adapter: snowflake=1.8.4
[2025-09-20T23:08:02.316+0000] {subprocess.py:93} INFO - [0m23:08:02  Unable to do partial parsing because saved manifest not found. Starting full parse.
[2025-09-20T23:08:02.732+0000] {subprocess.py:93} INFO - [0m23:08:02  [[33mWARNING[0m]: Configuration paths exist in your dbt_project.yml file which do not apply to any resources.
[2025-09-20T23:08:02.732+0000] {subprocess.py:93} INFO - There are 1 unused configuration paths:
[2025-09-20T23:08:02.732+0000] {subprocess.py:93} INFO - - models.espn_project.example
[2025-09-20T23:08:02.773+0000] {subprocess.py:93} INFO - [0m23:08:02  Found 7 models, 464 macros
[2025-09-20T23:08:02.775+0000] {subprocess.py:93} INFO - [0m23:08:02
[2025-09-20T23:08:03.318+0000] {subprocess.py:93} INFO - [0m23:08:03
[2025-09-20T23:08:03.319+0000] {subprocess.py:93} INFO - [0m23:08:03  Finished running  in 0 hours 0 minutes and 0.54 seconds (0.54s).
[2025-09-20T23:08:03.320+0000] {subprocess.py:93} INFO - [0m23:08:03  Encountered an error:
[2025-09-20T23:08:03.320+0000] {subprocess.py:93} INFO - Runtime Error
[2025-09-20T23:08:03.321+0000] {subprocess.py:93} INFO -   Database error while listing schemas in database "API_DATA_DB"
[2025-09-20T23:08:03.321+0000] {subprocess.py:93} INFO -   Database Error
[2025-09-20T23:08:03.321+0000] {subprocess.py:93} INFO -     250001 (08001): Failed to connect to DB: ggjmket-vqb12267.snowflakecomputing.com:443. Failed to authenticate: MFA authentication is required, but none of your current MFA methods are supported for programmatic authentication.
[2025-09-20T23:08:03.900+0000] {subprocess.py:97} INFO - Command exited with return code 2
[2025-09-20T23:08:03.900+0000] {taskinstance.py:441} INFO - ::group::Post task execution logs
[2025-09-20T23:08:03.904+0000] {taskinstance.py:2905} ERROR - Task failed with exception
Traceback (most recent call last):
  File "/home/airflow/.local/lib/python3.11/site-packages/airflow/models/taskinstance.py", line 465, in _execute_task
    result = _execute_callable(context=context, **execute_callable_kwargs)
             ^^^^^^^^^^^^^^^^^^^^^^^^^^^^^^^^^^^^^^^^^^^^^^^^^^^^^^^^^^^^^
  File "/home/airflow/.local/lib/python3.11/site-packages/airflow/models/taskinstance.py", line 432, in _execute_callable
    return execute_callable(context=context, **execute_callable_kwargs)
           ^^^^^^^^^^^^^^^^^^^^^^^^^^^^^^^^^^^^^^^^^^^^^^^^^^^^^^^^^^^^
  File "/home/airflow/.local/lib/python3.11/site-packages/airflow/models/baseoperator.py", line 401, in wrapper
    return func(self, *args, **kwargs)
           ^^^^^^^^^^^^^^^^^^^^^^^^^^^
  File "/home/airflow/.local/lib/python3.11/site-packages/airflow/operators/bash.py", line 243, in execute
    raise AirflowException(
airflow.exceptions.AirflowException: Bash command failed. The command returned a non-zero exit code 2.
[2025-09-20T23:08:03.906+0000] {taskinstance.py:1206} INFO - Marking task as FAILED. dag_id=espn_news_pipeline, task_id=dbt_run, run_id=manual__2025-09-20T23:07:46.340585+00:00, execution_date=20250920T230746, start_date=20250920T230800, end_date=20250920T230803
[2025-09-20T23:08:03.911+0000] {standard_task_runner.py:110} ERROR - Failed to execute job 9 for task dbt_run (Bash command failed. The command returned a non-zero exit code 2.; 102)
[2025-09-20T23:08:03.945+0000] {local_task_job_runner.py:243} INFO - Task exited with return code 1
[2025-09-20T23:08:03.952+0000] {taskinstance.py:3503} INFO - 0 downstream tasks scheduled from follow-on schedule check
[2025-09-20T23:08:03.954+0000] {local_task_job_runner.py:222} INFO - ::endgroup::
