[2025-09-21T00:00:02.768+0000] {local_task_job_runner.py:120} INFO - ::group::Pre task execution logs
[2025-09-21T00:00:02.784+0000] {taskinstance.py:2076} INFO - Dependencies all met for dep_context=non-requeueable deps ti=<TaskInstance: espn_news_pipeline.pull_api scheduled__2025-09-18T00:00:00+00:00 [queued]>
[2025-09-21T00:00:02.787+0000] {taskinstance.py:2076} INFO - Dependencies all met for dep_context=requeueable deps ti=<TaskInstance: espn_news_pipeline.pull_api scheduled__2025-09-18T00:00:00+00:00 [queued]>
[2025-09-21T00:00:02.787+0000] {taskinstance.py:2306} INFO - Starting attempt 1 of 1
[2025-09-21T00:00:02.792+0000] {taskinstance.py:2330} INFO - Executing <Task(PythonOperator): pull_api> on 2025-09-18 00:00:00+00:00
[2025-09-21T00:00:02.794+0000] {standard_task_runner.py:64} INFO - Started process 136 to run task
[2025-09-21T00:00:02.797+0000] {standard_task_runner.py:90} INFO - Running: ['airflow', 'tasks', 'run', 'espn_news_pipeline', 'pull_api', 'scheduled__2025-09-18T00:00:00+00:00', '--job-id', '13', '--raw', '--subdir', 'DAGS_FOLDER/news_pipeline.py', '--cfg-path', '/tmp/tmp5sfj6y74']
[2025-09-21T00:00:02.798+0000] {standard_task_runner.py:91} INFO - Job 13: Subtask pull_api
[2025-09-21T00:00:02.818+0000] {task_command.py:426} INFO - Running <TaskInstance: espn_news_pipeline.pull_api scheduled__2025-09-18T00:00:00+00:00 [running]> on host a4f5ed2786d6
[2025-09-21T00:00:02.841+0000] {taskinstance.py:2648} INFO - Exporting env vars: AIRFLOW_CTX_DAG_OWNER='airflow' AIRFLOW_CTX_DAG_ID='espn_news_pipeline' AIRFLOW_CTX_TASK_ID='pull_api' AIRFLOW_CTX_EXECUTION_DATE='2025-09-18T00:00:00+00:00' AIRFLOW_CTX_TRY_NUMBER='1' AIRFLOW_CTX_DAG_RUN_ID='scheduled__2025-09-18T00:00:00+00:00'
[2025-09-21T00:00:02.841+0000] {taskinstance.py:430} INFO - ::endgroup::
[2025-09-21T00:00:03.170+0000] {logging_mixin.py:188} INFO - using account: ggjmket-vqb12267
[2025-09-21T00:00:03.170+0000] {logging_mixin.py:188} INFO - using user: airflow_espn_named
[2025-09-21T00:00:03.170+0000] {connection.py:408} INFO - Snowflake Connector for Python Version: 3.11.0, Python Version: 3.11.9, Platform: Linux-6.10.14-linuxkit-aarch64-with-glibc2.36
[2025-09-21T00:00:03.172+0000] {taskinstance.py:441} INFO - ::group::Post task execution logs
[2025-09-21T00:00:03.173+0000] {taskinstance.py:2905} ERROR - Task failed with exception
Traceback (most recent call last):
  File "/home/airflow/.local/lib/python3.11/site-packages/airflow/models/taskinstance.py", line 465, in _execute_task
    result = _execute_callable(context=context, **execute_callable_kwargs)
             ^^^^^^^^^^^^^^^^^^^^^^^^^^^^^^^^^^^^^^^^^^^^^^^^^^^^^^^^^^^^^
  File "/home/airflow/.local/lib/python3.11/site-packages/airflow/models/taskinstance.py", line 432, in _execute_callable
    return execute_callable(context=context, **execute_callable_kwargs)
           ^^^^^^^^^^^^^^^^^^^^^^^^^^^^^^^^^^^^^^^^^^^^^^^^^^^^^^^^^^^^
  File "/home/airflow/.local/lib/python3.11/site-packages/airflow/models/baseoperator.py", line 401, in wrapper
    return func(self, *args, **kwargs)
           ^^^^^^^^^^^^^^^^^^^^^^^^^^^
  File "/home/airflow/.local/lib/python3.11/site-packages/airflow/operators/python.py", line 235, in execute
    return_value = self.execute_callable()
                   ^^^^^^^^^^^^^^^^^^^^^^^
  File "/home/airflow/.local/lib/python3.11/site-packages/airflow/operators/python.py", line 252, in execute_callable
    return self.python_callable(*self.op_args, **self.op_kwargs)
           ^^^^^^^^^^^^^^^^^^^^^^^^^^^^^^^^^^^^^^^^^^^^^^^^^^^^^
  File "/opt/airflow/dags/news_pipeline.py", line 17, in run_etl
    load_insert_raw()
  File "/opt/airflow/espn_etl/load_videos.py", line 21, in load_insert_raw
    conn = connect_to_schema()
           ^^^^^^^^^^^^^^^^^^^
  File "/opt/airflow/espn_etl/snowflake_connect.py", line 12, in connect_to_schema
    return snowflake.connector.connect(
           ^^^^^^^^^^^^^^^^^^^^^^^^^^^^
  File "/home/airflow/.local/lib/python3.11/site-packages/snowflake/connector/__init__.py", line 55, in Connect
    return SnowflakeConnection(**kwargs)
           ^^^^^^^^^^^^^^^^^^^^^^^^^^^^^
  File "/home/airflow/.local/lib/python3.11/site-packages/snowflake/connector/connection.py", line 451, in __init__
    self.connect(**kwargs)
  File "/home/airflow/.local/lib/python3.11/site-packages/snowflake/connector/connection.py", line 716, in connect
    self.__config(**kwargs)
  File "/home/airflow/.local/lib/python3.11/site-packages/snowflake/connector/connection.py", line 1227, in __config
    Error.errorhandler_wrapper(
  File "/home/airflow/.local/lib/python3.11/site-packages/snowflake/connector/errors.py", line 290, in errorhandler_wrapper
    handed_over = Error.hand_to_other_handler(
                  ^^^^^^^^^^^^^^^^^^^^^^^^^^^^
  File "/home/airflow/.local/lib/python3.11/site-packages/snowflake/connector/errors.py", line 348, in hand_to_other_handler
    connection.errorhandler(connection, cursor, error_class, error_value)
  File "/home/airflow/.local/lib/python3.11/site-packages/snowflake/connector/errors.py", line 221, in default_errorhandler
    raise error_class(
snowflake.connector.errors.ProgrammingError: 251006: 251006: Password is empty
[2025-09-21T00:00:03.175+0000] {taskinstance.py:1206} INFO - Marking task as FAILED. dag_id=espn_news_pipeline, task_id=pull_api, run_id=scheduled__2025-09-18T00:00:00+00:00, execution_date=20250918T000000, start_date=20250921T000002, end_date=20250921T000003
[2025-09-21T00:00:03.180+0000] {standard_task_runner.py:110} ERROR - Failed to execute job 13 for task pull_api (251006: 251006: Password is empty; 136)
[2025-09-21T00:00:03.196+0000] {local_task_job_runner.py:243} INFO - Task exited with return code 1
[2025-09-21T00:00:03.203+0000] {taskinstance.py:3503} INFO - 0 downstream tasks scheduled from follow-on schedule check
[2025-09-21T00:00:03.205+0000] {local_task_job_runner.py:222} INFO - ::endgroup::
